Workbook

Sheet 國定假日表
A1: 年度 | B1: 日期 | C1: 假日 | D1: 星期
A2: FY25 | B2: 45750 | C2: 清明節 | D2: ="("&RIGHT(TEXT(假日[[#This Row],[日期]],"[$-zh-TW]aaaa;@"),1)&")" -> (四)
B3: 45751 | C3: 兒童節 | D3: ="("&RIGHT(TEXT(假日[[#This Row],[日期]],"[$-zh-TW]aaaa;@"),1)&")" -> (五)
B4: 45778 | C4: 勞動節 | D4: ="("&RIGHT(TEXT(假日[[#This Row],[日期]],"[$-zh-TW]aaaa;@"),1)&")" -> (四)
B5: 45807 | C5: 端午節（補假） | D5: ="("&RIGHT(TEXT(假日[[#This Row],[日期]],"[$-zh-TW]aaaa;@"),1)&")" -> (五)
B6: 45929 | C6: 教師節（補假） | D6: ="("&RIGHT(TEXT(假日[[#This Row],[日期]],"[$-zh-TW]aaaa;@"),1)&")" -> (一)
B7: 45940 | C7: 國慶日 | D7: ="("&RIGHT(TEXT(假日[[#This Row],[日期]],"[$-zh-TW]aaaa;@"),1)&")" -> (五)
B8: 45954 | C8: 台灣光復日（補假） | D8: ="("&RIGHT(TEXT(假日[[#This Row],[日期]],"[$-zh-TW]aaaa;@"),1)&")" -> (五)
B9: 45936 | C9: 中秋節 | D9: ="("&RIGHT(TEXT(假日[[#This Row],[日期]],"[$-zh-TW]aaaa;@"),1)&")" -> (一)
B10: 46016 | C10: 行憲紀念日 | D10: ="("&RIGHT(TEXT(假日[[#This Row],[日期]],"[$-zh-TW]aaaa;@"),1)&")" -> (四)
B11: 46023 | C11: 元旦 | D11: ="("&RIGHT(TEXT(假日[[#This Row],[日期]],"[$-zh-TW]aaaa;@"),1)&")" -> (四)
B12: 46069 | C12: 農曆春節 | D12: ="("&RIGHT(TEXT(假日[[#This Row],[日期]],"[$-zh-TW]aaaa;@"),1)&")" -> (一)
B13: =B12+1 -> 46070 | C13: 農曆春節 | D13: ="("&RIGHT(TEXT(假日[[#This Row],[日期]],"[$-zh-TW]aaaa;@"),1)&")" -> (二)
B14: =B13+1 -> 46071 | C14: 農曆春節 | D14: ="("&RIGHT(TEXT(假日[[#This Row],[日期]],"[$-zh-TW]aaaa;@"),1)&")" -> (三)
B15: =B14+1 -> 46072 | C15: 農曆春節 | D15: ="("&RIGHT(TEXT(假日[[#This Row],[日期]],"[$-zh-TW]aaaa;@"),1)&")" -> (四)
B16: =B15+1 -> 46073 | C16: 農曆春節 | D16: ="("&RIGHT(TEXT(假日[[#This Row],[日期]],"[$-zh-TW]aaaa;@"),1)&")" -> (五)
B17: 46080 | C17: 二二八（補假） | D17: ="("&RIGHT(TEXT(假日[[#This Row],[日期]],"[$-zh-TW]aaaa;@"),1)&")" -> (五)
B18: 45929 | C18: 教師節（補假） | D18: ="("&RIGHT(TEXT(假日[[#This Row],[日期]],"[$-zh-TW]aaaa;@"),1)&")" -> (一)
B19: 45954 | C19: 光復節（補假） | D19: ="("&RIGHT(TEXT(假日[[#This Row],[日期]],"[$-zh-TW]aaaa;@"),1)&")" -> (五)
B20: 46016 | C20: 行憲紀念日 | D20: ="("&RIGHT(TEXT(假日[[#This Row],[日期]],"[$-zh-TW]aaaa;@"),1)&")" -> (四)
A21: FY26 | B21: 46115 | C21: 兒童節補假 | D21: ="("&RIGHT(TEXT(假日[[#This Row],[日期]],"[$-zh-TW]aaaa;@"),1)&")" -> (五)
B22: 46116 | C22: 兒童節 | D22: ="("&RIGHT(TEXT(假日[[#This Row],[日期]],"[$-zh-TW]aaaa;@"),1)&")" -> (六)
B23: 46117 | C23: 清明節 | D23: ="("&RIGHT(TEXT(假日[[#This Row],[日期]],"[$-zh-TW]aaaa;@"),1)&")" -> (日)
B24: 46118 | C24: 清明節補假 | D24: ="("&RIGHT(TEXT(假日[[#This Row],[日期]],"[$-zh-TW]aaaa;@"),1)&")" -> (一)
B25: 46143 | C25: 勞動節 | D25: ="("&RIGHT(TEXT(假日[[#This Row],[日期]],"[$-zh-TW]aaaa;@"),1)&")" -> (五)
B26: 46192 | C26: 端午節 | D26: ="("&RIGHT(TEXT(假日[[#This Row],[日期]],"[$-zh-TW]aaaa;@"),1)&")" -> (五)
B27: 46290 | C27: 中秋節 | D27: ="("&RIGHT(TEXT(假日[[#This Row],[日期]],"[$-zh-TW]aaaa;@"),1)&")" -> (五)
B28: 46293 | C28: 教師節 | D28: ="("&RIGHT(TEXT(假日[[#This Row],[日期]],"[$-zh-TW]aaaa;@"),1)&")" -> (一)
B29: 46304 | C29: 國慶日補假 | D29: ="("&RIGHT(TEXT(假日[[#This Row],[日期]],"[$-zh-TW]aaaa;@"),1)&")" -> (五)
B30: 46305 | C30: 國慶日 | D30: ="("&RIGHT(TEXT(假日[[#This Row],[日期]],"[$-zh-TW]aaaa;@"),1)&")" -> (六)
B31: 46320 | C31: 台灣光復節 | D31: ="("&RIGHT(TEXT(假日[[#This Row],[日期]],"[$-zh-TW]aaaa;@"),1)&")" -> (日)
B32: 46321 | C32: 台灣光復節補假 | D32: ="("&RIGHT(TEXT(假日[[#This Row],[日期]],"[$-zh-TW]aaaa;@"),1)&")" -> (一)
B33: 46381 | C33: 行憲紀念日 | D33: ="("&RIGHT(TEXT(假日[[#This Row],[日期]],"[$-zh-TW]aaaa;@"),1)&")" -> (五)
... B42: 46447 | C42: 和平紀念日補假 | D42: ="("&RIGHT(TEXT(假日[[#This Row],[日期]],"[$-zh-TW]aaaa;@"),1)&")" -> (一)

Sheet 年度工作天
A1: FY24
B2: 起始日 | C2: 終止日 | D2: 工作天數
B3: 45383 | C3: =EOMONTH(B3,0) -> 45412 | D3: 22 | F3: =SUM(表格1[工作天數]) -> 261
B4: 45413 | C4: =EOMONTH(B4,0) -> 45443 | D4: 23
B5: 45444 | C5: =EOMONTH(B5,0) -> 45473 | D5: 20
B6: 45474 | C6: =EOMONTH(B6,0) -> 45504 | D6: 23
B7: 45505 | C7: =EOMONTH(B7,0) -> 45535 | D7: 22
B8: 45536 | C8: =EOMONTH(B8,0) -> 45565 | D8: 21
B9: 45566 | C9: =EOMONTH(B9,0) -> 45596 | D9: 23
B10: 45597 | C10: =EOMONTH(B10,0) -> 45626 | D10: 21
B11: 45627 | C11: =EOMONTH(B11,0) -> 45657 | D11: 22
B12: 45658 | C12: =EOMONTH(B12,0) -> 45688 | D12: 23
B13: 45689 | C13: =EOMONTH(B13,0) -> 45716 | D13: 20
B14: 45717 | C14: =EOMONTH(B14,0) -> 45747 | D14: 21
A18: FY25
B19: 起始日 | C19: 終止日 | D19: 工作天數
B20: 45748 | C20: =EOMONTH(B20,0) -> 45777 | D20: 20 | F20: =SUM(表格1_4[工作天數]) -> 245
B21: 45778 | C21: =EOMONTH(B21,0) -> 45808 | D21: 20
B22: 45809 | C22: =EOMONTH(B22,0) -> 45838 | D22: 21
B23: 45839 | C23: =EOMONTH(B23,0) -> 45869 | D23: 23
B24: 45870 | C24: =EOMONTH(B24,0) -> 45900 | D24: 21
B25: 45901 | C25: =EOMONTH(B25,0) -> 45930 | D25: 21
B26: 45931 | C26: =EOMONTH(B26,0) -> 45961 | D26: 20
B27: 45962 | C27: =EOMONTH(B27,0) -> 45991 | D27: 20
B28: 45992 | C28: =EOMONTH(B28,0) -> 46022 | D28: 22
B29: 46023 | C29: =EOMONTH(B29,0) -> 46053 | D29: 21
B30: 46054 | C30: =EOMONTH(B30,0) -> 46081 | D30: 14
B31: 46082 | C31: =EOMONTH(B31,0) -> 46112 | D31: 22
A34: FY26
B35: 起始日 | C35: 終止日 | D35: 工作天數
B36: 46113 | C36: =EOMONTH(B36,0) -> 46142 | D36: 20 | F36: =SUM(表格1_46[工作天數]) -> 246
B37: 46143 | C37: =EOMONTH(B37,0) -> 46173 | D37: 20
B38: 46174 | C38: =EOMONTH(B38,0) -> 46203 | D38: 21
B39: 46204 | C39: =EOMONTH(B39,0) -> 46234 | D39: 23
B40: 46235 | C40: =EOMONTH(B40,0) -> 46265 | D40: 21
B41: 46266 | C41: =EOMONTH(B41,0) -> 46295 | D41: 20
B42: 46296 | C42: =EOMONTH(B42,0) -> 46326 | D42: 20
B43: 46327 | C43: =EOMONTH(B43,0) -> 46356 | D43: 21
B44: 46357 | C44: =EOMONTH(B44,0) -> 46387 | D44: 22
B45: 46388 | C45: =EOMONTH(B45,0) -> 46418 | D45: 20
...

Sheet 管道定義
A1: 樞紐表管道 | B1: 對應後的管道
A2: 網站 | B2: WEB
A3: 團購 | B3: KOL
A4: EC | B4: EC
A5: 電銷 | B5: TM

Sheet 2604WEB&KOL
B1: 付款狀態 | C1: 已付款
A3: 事業 | B3: 商品貨號 | C3: 訂單日期 | D3: 銷貨管道 | E3: 加總 - 數量 | F3: 加總 - 未稅價格
A4: =IFERROR(VLOOKUP(B4,[1]銷貨單品號主檔!$A:$D,4,0),"學習周邊") -> 生活周邊 | B4: 20170H020 | C4: 2026/4/20 | D4: 網站 | E4: 1 | F4: 523.80952
A5: =IFERROR(VLOOKUP(B5,[1]銷貨單品號主檔!$A:$D,4,0),"學習周邊") -> 生活周邊 | B5: 20180H041 | C5: 2026/4/20 | D5: 網站 | E5: 1 | F5: 205.71429
A6: =IFERROR(VLOOKUP(B6,[1]銷貨單品號主檔!$A:$D,4,0),"學習周邊") -> 學習周邊 | B6: 20180PB0H | C6: 2026/4/7 | D6: 網站 | E6: 0 | F6: 0
A7: =IFERROR(VLOOKUP(B7,[1]銷貨單品號主檔!$A:$D,4,0),"學習周邊") -> 學習周邊 | B7: 20180PM01 | C7: 2026/4/1 | D7: 網站 | E7: 0 | F7: 0
A8: =IFERROR(VLOOKUP(B8,[1]銷貨單品號主檔!$A:$D,4,0),"學習周邊") -> 學習周邊 | B8: 20180PM01 | C8: 2026/4/7 | D8: 網站 | E8: 0 | F8: 0
A9: =IFERROR(VLOOKUP(B9,[1]銷貨單品號主檔!$A:$D,4,0),"學習周邊") -> 學習周邊 | B9: 20180PM01 | C9: 2026/4/8 | D9: 網站 | E9: 0 | F9: 0
A10: =IFERROR(VLOOKUP(B10,[1]銷貨單品號主檔!$A:$D,4,0),"學習周邊") -> 學習周邊 | B10: 20180PM01 | C10: 2026/4/10 | D10: 網站 | E10: 0 | F10: 0
A11: =IFERROR(VLOOKUP(B11,[1]銷貨單品號主檔!$A:$D,4,0),"學習周邊") -> 學習周邊 | B11: 20180PM01 | C11: 2026/4/11 | D11: 網站 | E11: 0 | F11: 0
A12: =IFERROR(VLOOKUP(B12,[1]銷貨單品號主檔!$A:$D,4,0),"學習周邊") -> 學習周邊 | B12: 20180PM01 | C12: 2026/4/12 | D12: 網站 | E12: 0 | F12: 0
A13: =IFERROR(VLOOKUP(B13,[1]銷貨單品號主檔!$A:$D,4,0),"學習周邊") -> 學習周邊 | B13: 20180PM01 | C13: 2026/4/13 | D13: 網站 | E13: 0 | F13: 0
A14: =IFERROR(VLOOKUP(B14,[1]銷貨單品號主檔!$A:$D,4,0),"學習周邊") -> 學習周邊 | B14: 20180PM01 | C14: 2026/4/14 | D14: 網站 | E14: 0 | F14: 0
A15: =IFERROR(VLOOKUP(B15,[1]銷貨單品號主檔!$A:$D,4,0),"學習周邊") -> 學習周邊 | B15: 20180PM01 | C15: 2026/4/15 | D15: 網站 | E15: 0 | F15: 0
... A1163: =IFERROR(VLOOKUP(B1163,[1]銷貨單品號主檔!$A:$D,4,0),"學習周邊") -> 生活周邊 | B1163: 20260H003 | C1163: 2026/4/29 | D1163: 網站 | E1163: 1 | F1163: 284.7619
A1164: =IFERROR(VLOOKUP(B1164,[1]銷貨單品號主檔!$A:$D,4,0),"學習周邊") -> 0
A1165: =IFERROR(VLOOKUP(B1165,[1]銷貨單品號主檔!$A:$D,4,0),"學習周邊") -> 0
A1166: =IFERROR(VLOOKUP(B1166,[1]銷貨單品號主檔!$A:$D,4,0),"學習周邊") -> 0
A1167: =IFERROR(VLOOKUP(B1167,[1]銷貨單品號主檔!$A:$D,4,0),"學習周邊") -> 0
A1168: =IFERROR(VLOOKUP(B1168,[1]銷貨單品號主檔!$A:$D,4,0),"學習周邊") -> 0
A1169: =IFERROR(VLOOKUP(B1169,[1]銷貨單品號主檔!$A:$D,4,0),"學習周邊") -> 0
A1170: =IFERROR(VLOOKUP(B1170,[1]銷貨單品號主檔!$A:$D,4,0),"學習周邊") -> 0
A1171: =IFERROR(VLOOKUP(B1171,[1]銷貨單品號主檔!$A:$D,4,0),"學習周邊") -> 0
A1172: =IFERROR(VLOOKUP(B1172,[1]銷貨單品號主檔!$A:$D,4,0),"學習周邊") -> 0
A1173: =IFERROR(VLOOKUP(B1173,[1]銷貨單品號主檔!$A:$D,4,0),"學習周邊") -> 0
A1174: =IFERROR(VLOOKUP(B1174,[1]銷貨單品號主檔!$A:$D,4,0),"學習周邊") -> 0
A1175: =IFERROR(VLOOKUP(B1175,[1]銷貨單品號主檔!$A:$D,4,0),"學習周邊") -> 0
... A1725: =IFERROR(VLOOKUP(B1725,[1]銷貨單品號主檔!$A:$D,4,0),"學習周邊") -> 0

Sheet 2604 EC
B1: 訂單狀態 | C1: (多重項目) | F1: 管道
F2: EC
A3: 事業 | B3: 主商品貨號 | C3: 訂單成立日期 | D3: 加總 - 數量 | E3: 加總 - 未稅價格 | F3: EC
A4: =IFERROR(VLOOKUP(B4,[1]銷貨單品號主檔!$A:$D,4,0),"學習周邊") -> 學習周邊 | B4: 20250FXAM | C4: 2026/4/1 | D4: 2 | E4: 569.52381 | F4: EC
A5: =IFERROR(VLOOKUP(B5,[1]銷貨單品號主檔!$A:$D,4,0),"學習周邊") -> 學習周邊 | B5: 20250FXAM | C5: 2026/4/2 | D5: 1 | E5: 284.7619 | F5: EC
A6: =IFERROR(VLOOKUP(B6,[1]銷貨單品號主檔!$A:$D,4,0),"學習周邊") -> 學習周邊 | B6: 20250FXAM | C6: 2026/4/3 | D6: 3 | E6: 569.52381 | F6: EC
A7: =IFERROR(VLOOKUP(B7,[1]銷貨單品號主檔!$A:$D,4,0),"學習周邊") -> 學習周邊 | B7: 20250FXAM | C7: 2026/4/4 | D7: 7 | E7: 1423.8095 | F7: EC
A8: =IFERROR(VLOOKUP(B8,[1]銷貨單品號主檔!$A:$D,4,0),"學習周邊") -> 學習周邊 | B8: 20250FXAM | C8: 2026/4/5 | D8: 3 | E8: 854.28571 | F8: EC
A9: =IFERROR(VLOOKUP(B9,[1]銷貨單品號主檔!$A:$D,4,0),"學習周邊") -> 學習周邊 | B9: 20250FXAM | C9: 2026/4/6 | D9: 2 | E9: 569.52381 | F9: EC
A10: =IFERROR(VLOOKUP(B10,[1]銷貨單品號主檔!$A:$D,4,0),"學習周邊") -> 學習周邊 | B10: 20250FXAM | C10: 2026/4/7 | D10: 7 | E10: 1423.8095 | F10: EC
A11: =IFERROR(VLOOKUP(B11,[1]銷貨單品號主檔!$A:$D,4,0),"學習周邊") -> 學習周邊 | B11: 20250FXAM | C11: 2026/4/8 | D11: 5 | E11: 1139.0476 | F11: EC
A12: =IFERROR(VLOOKUP(B12,[1]銷貨單品號主檔!$A:$D,4,0),"學習周邊") -> 學習周邊 | B12: 20250FXAM | C12: 2026/4/11 | D12: 1 | E12: 284.7619 | F12: EC
A13: =IFERROR(VLOOKUP(B13,[1]銷貨單品號主檔!$A:$D,4,0),"學習周邊") -> 學習周邊 | B13: 20250FXAM | C13: 2026/4/12 | D13: 3 | E13: 284.7619 | F13: EC
A14: =IFERROR(VLOOKUP(B14,[1]銷貨單品號主檔!$A:$D,4,0),"學習周邊") -> 學習周邊 | B14: 20250FXAM | C14: 2026/4/15 | D14: 2 | E14: 569.52381 | F14: EC
A15: =IFERROR(VLOOKUP(B15,[1]銷貨單品號主檔!$A:$D,4,0),"學習周邊") -> 學習周邊 | B15: 20250FXAM | C15: 2026/4/16 | D15: 1 | E15: 284.7619 | F15: EC
... A326: =IFERROR(VLOOKUP(B326,[1]銷貨單品號主檔!$A:$D,4,0),"學習周邊") -> 學習周邊 | B326: 20252CXAD | C326: 2026/4/24 | D326: 1 | E326: 752.38095 | F326: EC
A327: =IFERROR(VLOOKUP(B327,[1]銷貨單品號主檔!$A:$D,4,0),"學習周邊") -> 0 | F327: EC
A328: =IFERROR(VLOOKUP(B328,[1]銷貨單品號主檔!$A:$D,4,0),"學習周邊") -> 0 | F328: EC
A329: =IFERROR(VLOOKUP(B329,[1]銷貨單品號主檔!$A:$D,4,0),"學習周邊") -> 0 | F329: EC
A330: =IFERROR(VLOOKUP(B330,[1]銷貨單品號主檔!$A:$D,4,0),"學習周邊") -> 0 | F330: EC
A331: =IFERROR(VLOOKUP(B331,[1]銷貨單品號主檔!$A:$D,4,0),"學習周邊") -> 0 | F331: EC
A332: =IFERROR(VLOOKUP(B332,[1]銷貨單品號主檔!$A:$D,4,0),"學習周邊") -> 0 | F332: EC
A333: =IFERROR(VLOOKUP(B333,[1]銷貨單品號主檔!$A:$D,4,0),"學習周邊") -> 0 | F333: EC
A334: =IFERROR(VLOOKUP(B334,[1]銷貨單品號主檔!$A:$D,4,0),"學習周邊") -> 0 | F334: EC
A335: =IFERROR(VLOOKUP(B335,[1]銷貨單品號主檔!$A:$D,4,0),"學習周邊") -> 0 | F335: EC
A336: =IFERROR(VLOOKUP(B336,[1]銷貨單品號主檔!$A:$D,4,0),"學習周邊") -> 0 | F336: EC
A337: =IFERROR(VLOOKUP(B337,[1]銷貨單品號主檔!$A:$D,4,0),"學習周邊") -> 0 | F337: EC
A338: =IFERROR(VLOOKUP(B338,[1]銷貨單品號主檔!$A:$D,4,0),"學習周邊") -> 0 | F338: EC
... A494: =IFERROR(VLOOKUP(B494,[1]銷貨單品號主檔!$A:$D,4,0),"學習周邊") -> 0 | F494: EC

Sheet 2604TM
B1: 發貨年月 | C1: 202604
A3: 事業 | B3: 商品編號 | C3: 發貨日期 | D3: 管道 | E3: 商品數量 | F3: 含稅金額 | G3: 加總 - 未稅價格 | H3: 發貨日期
A4: 學習周邊 | B4: 20190PB04 | C4: 2026-04-01 | D4: 電銷 | E4: 3 | F4: 0 | G4: 0 | H4: 46113
A5: 學習 | B5: 20201M401 | C5: 2026-04-01 | D5: 電銷 | E5: 1 | F5: 100 | G5: 95.238095 | H5: 46113
A6: 學習周邊 | B6: 20201PB0A | C6: 2026-04-02 | D6: 電銷 | E6: 3 | F6: 0 | G6: 0 | H6: 46114
A7: 學習周邊 | B7: 20201PB0A | C7: 2026-04-07 | D7: 電銷 | E7: 2 | F7: 0 | G7: 0 | H7: 46119
A8: 學習周邊 | B8: 20201PB0A | C8: 2026-04-09 | D8: 電銷 | E8: 4 | F8: 0 | G8: 0 | H8: 46121
A9: 學習周邊 | B9: 20201PB0A | C9: 2026-04-10 | D9: 電銷 | E9: 3 | F9: 0 | G9: 0 | H9: 46122
A10: 學習周邊 | B10: 20201PB0A | C10: 2026-04-14 | D10: 電銷 | E10: 3 | F10: 0 | G10: 0 | H10: 46126
A11: 學習周邊 | B11: 20201PB0A | C11: 2026-04-15 | D11: 電銷 | E11: 2 | F11: 0 | G11: 0 | H11: 46127
A12: 學習周邊 | B12: 20201PB0A | C12: 2026-04-16 | D12: 電銷 | E12: 1 | F12: 0 | G12: 0 | H12: 46128
A13: 學習周邊 | B13: 20201PB0A | C13: 2026-04-20 | D13: 電銷 | E13: 4 | F13: 0 | G13: 0 | H13: 46132
A14: 學習周邊 | B14: 20201PB0A | C14: 2026-04-21 | D14: 電銷 | E14: 5 | F14: 0 | G14: 0 | H14: 46133
A15: 學習周邊 | B15: 20201PB0A | C15: 2026-04-22 | D15: 電銷 | E15: 1 | F15: 0 | G15: 0 | H15: 46134
... A496: 學習周邊 | B496: 3125HP011 | C496: 2026-04-08 | D496: 電銷 | E496: 1 | F496: 0 | G496: 0 | H496: 46120
A497: 0 | G497: 0
A498: 0 | G498: 0
A499: 0 | G499: 0
A500: 0 | G500: 0
A501: 0 | G501: 0
A502: 0 | G502: 0
A503: 0 | G503: 0
A504: 0 | G504: 0
A505: 0 | G505: 0
A506: 0 | G506: 0
A507: 0 | G507: 0
A508: 0 | G508: 0
... A699: 0 | G699: 0

Sheet 2605WEB&KOL
B1: 付款狀態 | C1: 已付款
A3: 事業 | B3: 商品貨號 | C3: 訂單日期 | D3: 銷貨管道 | E3: 加總 - 數量 | F3: 加總 - 未稅價格
A4: =IFERROR(VLOOKUP(B4,[1]銷貨單品號主檔!$A:$D,4,0),"學習周邊") -> 學習周邊 | B4: 20190PP04 | C4: 2026/5/1 | D4: 網站 | E4: 0 | F4: 0
A5: =IFERROR(VLOOKUP(B5,[1]銷貨單品號主檔!$A:$D,4,0),"學習周邊") -> 學習周邊 | B5: 20190PP04 | C5: 2026/5/2 | D5: 網站 | E5: 0 | F5: 0
A6: =IFERROR(VLOOKUP(B6,[1]銷貨單品號主檔!$A:$D,4,0),"學習周邊") -> 學習周邊 | B6: 20190PP04 | C6: 2026/5/3 | D6: 網站 | E6: 0 | F6: 0
A7: =IFERROR(VLOOKUP(B7,[1]銷貨單品號主檔!$A:$D,4,0),"學習周邊") -> 學習周邊 | B7: 20190PP04 | C7: 2026/5/4 | D7: 網站 | E7: 0 | F7: 0
A8: =IFERROR(VLOOKUP(B8,[1]銷貨單品號主檔!$A:$D,4,0),"學習周邊") -> 生活周邊 | B8: 20210H002 | C8: 2026/5/3 | D8: 網站 | E8: 1 | F8: 189.52381
A9: =IFERROR(VLOOKUP(B9,[1]銷貨單品號主檔!$A:$D,4,0),"學習周邊") -> 生活周邊 | B9: 20210KJ00 | C9: 2026/5/2 | D9: 網站 | E9: 1 | F9: 1903.8095
A10: =IFERROR(VLOOKUP(B10,[1]銷貨單品號主檔!$A:$D,4,0),"學習周邊") -> 生活周邊 | B10: 20210KJ00 | C10: 2026/5/5 | D10: 網站 | E10: 1 | F10: 1903.8095
A11: =IFERROR(VLOOKUP(B11,[1]銷貨單品號主檔!$A:$D,4,0),"學習周邊") -> 學習周邊 | B11: 20210PQ01 | C11: 2026/5/6 | D11: 網站 | E11: 0 | F11: 0
A12: =IFERROR(VLOOKUP(B12,[1]銷貨單品號主檔!$A:$D,4,0),"學習周邊") -> 生活周邊 | B12: 20220EA00 | C12: 2026/5/5 | D12: 網站 | E12: 2 | F12: 38.095238
A13: =IFERROR(VLOOKUP(B13,[1]銷貨單品號主檔!$A:$D,4,0),"學習周邊") -> 生活周邊 | B13: 20220EA00 | C13: 2026/5/6 | D13: 網站 | E13: 0 | F13: 0
A14: =IFERROR(VLOOKUP(B14,[1]銷貨單品號主檔!$A:$D,4,0),"學習周邊") -> 生活周邊 | B14: 20220EB00 | C14: 2026/5/5 | D14: 網站 | E14: 2 | F14: 38.095238
A15: =IFERROR(VLOOKUP(B15,[1]銷貨單品號主檔!$A:$D,4,0),"學習周邊") -> 生活周邊 | B15: 20220EC00 | C15: 2026/5/5 | D15: 網站 | E15: 1 | F15: 167.61905
... A158: =IFERROR(VLOOKUP(B158,[1]銷貨單品號主檔!$A:$D,4,0),"學習周邊") -> 生活周邊 | B158: 20260H003 | C158: 2026/5/3 | D158: 網站 | E158: 2 | F158: 664.7619
A159: =IFERROR(VLOOKUP(B159,[1]銷貨單品號主檔!$A:$D,4,0),"學習周邊") -> 0
A160: =IFERROR(VLOOKUP(B160,[1]銷貨單品號主檔!$A:$D,4,0),"學習周邊") -> 0
A161: =IFERROR(VLOOKUP(B161,[1]銷貨單品號主檔!$A:$D,4,0),"學習周邊") -> 0
A162: =IFERROR(VLOOKUP(B162,[1]銷貨單品號主檔!$A:$D,4,0),"學習周邊") -> 0
A163: =IFERROR(VLOOKUP(B163,[1]銷貨單品號主檔!$A:$D,4,0),"學習周邊") -> 0
A164: =IFERROR(VLOOKUP(B164,[1]銷貨單品號主檔!$A:$D,4,0),"學習周邊") -> 0
A165: =IFERROR(VLOOKUP(B165,[1]銷貨單品號主檔!$A:$D,4,0),"學習周邊") -> 0
A166: =IFERROR(VLOOKUP(B166,[1]銷貨單品號主檔!$A:$D,4,0),"學習周邊") -> 0
A167: =IFERROR(VLOOKUP(B167,[1]銷貨單品號主檔!$A:$D,4,0),"學習周邊") -> 0
A168: =IFERROR(VLOOKUP(B168,[1]銷貨單品號主檔!$A:$D,4,0),"學習周邊") -> 0
A169: =IFERROR(VLOOKUP(B169,[1]銷貨單品號主檔!$A:$D,4,0),"學習周邊") -> 0
A170: =IFERROR(VLOOKUP(B170,[1]銷貨單品號主檔!$A:$D,4,0),"學習周邊") -> 0
... A1725: =IFERROR(VLOOKUP(B1725,[1]銷貨單品號主檔!$A:$D,4,0),"學習周邊") -> 0

Sheet 2605EC
B1: 訂單狀態 | C1: (多重項目)
A3: 事業 | B3: 主商品貨號 | C3: 訂單成立日期 | D3: 加總 - 數量 | E3: 加總 - 未稅價格 | F3: 管道
A4: =IFERROR(VLOOKUP(B4,[1]銷貨單品號主檔!$A:$D,4,0),"學習周邊") -> 學習周邊 | B4: 20250FXAM | C4: 2026/5/3 | D4: 3 | E4: 854.28571 | F4: EC
A5: =IFERROR(VLOOKUP(B5,[1]銷貨單品號主檔!$A:$D,4,0),"學習周邊") -> 學習周邊 | B5: 20250FXAM | C5: 2026/5/4 | D5: 1 | E5: 284.7619 | F5: EC
A6: =IFERROR(VLOOKUP(B6,[1]銷貨單品號主檔!$A:$D,4,0),"學習周邊") -> 學習周邊 | B6: 20250FXAM | C6: 2026/5/5 | D6: 13 | E6: 1993.3333 | F6: EC
A7: =IFERROR(VLOOKUP(B7,[1]銷貨單品號主檔!$A:$D,4,0),"學習周邊") -> 學習周邊 | B7: 20250FXAM | C7: 2026/5/6 | D7: 3 | E7: 569.52381 | F7: EC
A8: =IFERROR(VLOOKUP(B8,[1]銷貨單品號主檔!$A:$D,4,0),"學習周邊") -> 學習周邊 | B8: 20240FB00 | C8: 2026/5/1 | D8: 1 | E8: 951.42857 | F8: EC
A9: =IFERROR(VLOOKUP(B9,[1]銷貨單品號主檔!$A:$D,4,0),"學習周邊") -> 學習周邊 | B9: 20240FB00 | C9: 2026/5/2 | D9: 1 | E9: 951.42857 | F9: EC
A10: =IFERROR(VLOOKUP(B10,[1]銷貨單品號主檔!$A:$D,4,0),"學習周邊") -> 學習周邊 | B10: 20240FB00 | C10: 2026/5/4 | D10: 1 | E10: 1140.9524 | F10: EC
A11: =IFERROR(VLOOKUP(B11,[1]銷貨單品號主檔!$A:$D,4,0),"學習周邊") -> 學習周邊 | B11: 20240FB00 | C11: 2026/5/5 | D11: 3 | E11: 3233.3333 | F11: EC
A12: =IFERROR(VLOOKUP(B12,[1]銷貨單品號主檔!$A:$D,4,0),"學習周邊") -> 學習周邊 | B12: 20240FB00 | C12: 2026/5/6 | D12: 1 | E12: 1140.9524 | F12: EC
A13: =IFERROR(VLOOKUP(B13,[1]銷貨單品號主檔!$A:$D,4,0),"學習周邊") -> 學習周邊 | B13: 20221C611 | C13: 2026/5/3 | D13: 1 | E13: 189.52381 | F13: EC
A14: =IFERROR(VLOOKUP(B14,[1]銷貨單品號主檔!$A:$D,4,0),"學習周邊") -> 學習周邊 | B14: 20221C611 | C14: 2026/5/5 | D14: 1 | E14: 189.52381 | F14: EC
A15: =IFERROR(VLOOKUP(B15,[1]銷貨單品號主檔!$A:$D,4,0),"學習周邊") -> 學習 | B15: 20250FA00 | C15: 2026/5/1 | D15: 2 | E15: 4188.5714 | F15: EC
... A81: =IFERROR(VLOOKUP(B81,[1]銷貨單品號主檔!$A:$D,4,0),"學習周邊") -> 生活周邊 | B81: 20220KG00 | C81: 2026/5/5 | D81: 1 | E81: 760.95238 | F81: EC
A82: =IFERROR(VLOOKUP(B82,[1]銷貨單品號主檔!$A:$D,4,0),"學習周邊") -> 0 | F82: EC
A83: =IFERROR(VLOOKUP(B83,[1]銷貨單品號主檔!$A:$D,4,0),"學習周邊") -> 0 | F83: EC
A84: =IFERROR(VLOOKUP(B84,[1]銷貨單品號主檔!$A:$D,4,0),"學習周邊") -> 0 | F84: EC
A85: =IFERROR(VLOOKUP(B85,[1]銷貨單品號主檔!$A:$D,4,0),"學習周邊") -> 0 | F85: EC
A86: =IFERROR(VLOOKUP(B86,[1]銷貨單品號主檔!$A:$D,4,0),"學習周邊") -> 0 | F86: EC
A87: =IFERROR(VLOOKUP(B87,[1]銷貨單品號主檔!$A:$D,4,0),"學習周邊") -> 0 | F87: EC
A88: =IFERROR(VLOOKUP(B88,[1]銷貨單品號主檔!$A:$D,4,0),"學習周邊") -> 0 | F88: EC
A89: =IFERROR(VLOOKUP(B89,[1]銷貨單品號主檔!$A:$D,4,0),"學習周邊") -> 0 | F89: EC
A90: =IFERROR(VLOOKUP(B90,[1]銷貨單品號主檔!$A:$D,4,0),"學習周邊") -> 0 | F90: EC
A91: =IFERROR(VLOOKUP(B91,[1]銷貨單品號主檔!$A:$D,4,0),"學習周邊") -> 0 | F91: EC
A92: =IFERROR(VLOOKUP(B92,[1]銷貨單品號主檔!$A:$D,4,0),"學習周邊") -> 0 | F92: EC
A93: =IFERROR(VLOOKUP(B93,[1]銷貨單品號主檔!$A:$D,4,0),"學習周邊") -> 0 | F93: EC
... A494: =IFERROR(VLOOKUP(B494,[1]銷貨單品號主檔!$A:$D,4,0),"學習周邊") -> 0 | F494: EC

Sheet 2605TM
B1: 發貨年月 | C1: 202605
A3: 事業 | B3: 商品編號 | C3: 發貨日期 | D3: 管道 | E3: 商品數量 | F3: 含稅金額 | G3: 加總 - 未稅價格 | H3: 發貨日期
A4: =IFERROR(VLOOKUP(B4,[1]銷貨單品號主檔!$A:$D,4,0),"學習周邊") -> 學習周邊 | B4: 20201PB0A | C4: 2026-05-01 | D4: 電銷 | E4: 2 | F4: 0 | G4: =F4/1.05 -> 0 | H4: =IF(C4="","",TEXT(C4,"YYYY/M/D")*1) -> 46143
A5: =IFERROR(VLOOKUP(B5,[1]銷貨單品號主檔!$A:$D,4,0),"學習周邊") -> 學習周邊 | B5: 20201PB0A | C5: 2026-05-04 | D5: 電銷 | E5: 2 | F5: 0 | G5: =F5/1.05 -> 0 | H5: =IF(C5="","",TEXT(C5,"YYYY/M/D")*1) -> 46146
A6: =IFERROR(VLOOKUP(B6,[1]銷貨單品號主檔!$A:$D,4,0),"學習周邊") -> 學習周邊 | B6: 20210PP08 | C6: 2026-05-04 | D6: 電銷 | E6: 1 | F6: 0 | G6: =F6/1.05 -> 0 | H6: =IF(C6="","",TEXT(C6,"YYYY/M/D")*1) -> 46146
A7: =IFERROR(VLOOKUP(B7,[1]銷貨單品號主檔!$A:$D,4,0),"學習周邊") -> 學習 | B7: 20220M601 | C7: 2026-05-06 | D7: 電銷 | E7: 1 | F7: 800 | G7: =F7/1.05 -> 761.90476 | H7: =IF(C7="","",TEXT(C7,"YYYY/M/D")*1) -> 46148
A8: =IFERROR(VLOOKUP(B8,[1]銷貨單品號主檔!$A:$D,4,0),"學習周邊") -> 學習 | B8: 20220MY00 | C8: 2026-05-04 | D8: 電銷 | E8: 1 | F8: 4500 | G8: =F8/1.05 -> 4285.7143 | H8: =IF(C8="","",TEXT(C8,"YYYY/M/D")*1) -> 46146
A9: =IFERROR(VLOOKUP(B9,[1]銷貨單品號主檔!$A:$D,4,0),"學習周邊") -> 學習周邊 | B9: 20221C6B6 | C9: 2026-05-04 | D9: 電銷 | E9: 1 | F9: 0 | G9: =F9/1.05 -> 0 | H9: =IF(C9="","",TEXT(C9,"YYYY/M/D")*1) -> 46146
A10: =IFERROR(VLOOKUP(B10,[1]銷貨單品號主檔!$A:$D,4,0),"學習周邊") -> 學習周邊 | B10: 20224PB02 | C10: 2026-05-04 | D10: 電銷 | E10: 2 | F10: 0 | G10: =F10/1.05 -> 0 | H10: =IF(C10="","",TEXT(C10,"YYYY/M/D")*1) -> 46146
A11: =IFERROR(VLOOKUP(B11,[1]銷貨單品號主檔!$A:$D,4,0),"學習周邊") -> 學習 | B11: 20230MY00 | C11: 2026-05-04 | D11: 電銷 | E11: 3 | F11: 14400 | G11: =F11/1.05 -> 13714.286 | H11: =IF(C11="","",TEXT(C11,"YYYY/M/D")*1) -> 46146
A12: =IFERROR(VLOOKUP(B12,[1]銷貨單品號主檔!$A:$D,4,0),"學習周邊") -> 學習 | B12: 20230MY00 | C12: 2026-05-05 | D12: 電銷 | E12: 1 | F12: 4800 | G12: =F12/1.05 -> 4571.4286 | H12: =IF(C12="","",TEXT(C12,"YYYY/M/D")*1) -> 46147
A13: =IFERROR(VLOOKUP(B13,[1]銷貨單品號主檔!$A:$D,4,0),"學習周邊") -> 學習 | B13: 20230MY00 | C13: 2026-05-06 | D13: 電銷 | E13: 2 | F13: 9600 | G13: =F13/1.05 -> 9142.8571 | H13: =IF(C13="","",TEXT(C13,"YYYY/M/D")*1) -> 46148
A14: =IFERROR(VLOOKUP(B14,[1]銷貨單品號主檔!$A:$D,4,0),"學習周邊") -> 學習周邊 | B14: 20233PB02 | C14: 2026-05-01 | D14: 電銷 | E14: 1 | F14: 0 | G14: =F14/1.05 -> 0 | H14: =IF(C14="","",TEXT(C14,"YYYY/M/D")*1) -> 46143
A15: =IFERROR(VLOOKUP(B15,[1]銷貨單品號主檔!$A:$D,4,0),"學習周邊") -> 學習周邊 | B15: 20233PB02 | C15: 2026-05-04 | D15: 電銷 | E15: 2 | F15: 0 | G15: =F15/1.05 -> 0 | H15: =IF(C15="","",TEXT(C15,"YYYY/M/D")*1) -> 46146
... A61: =IFERROR(VLOOKUP(B61,[1]銷貨單品號主檔!$A:$D,4,0),"學習周邊") -> 學習周邊 | B61: 3125HP009 | C61: 2026-05-06 | D61: 電銷 | E61: 1 | F61: 0 | G61: =F61/1.05 -> 0 | H61: =IF(C61="","",TEXT(C61,"YYYY/M/D")*1) -> 46148
A62: =IFERROR(VLOOKUP(B62,[1]銷貨單品號主檔!$A:$D,4,0),"學習周邊") -> 0 | G62: =F62/1.05 -> 0 | H62: =IF(C62="","",TEXT(C62,"YYYY/M/D")*1)
A63: =IFERROR(VLOOKUP(B63,[1]銷貨單品號主檔!$A:$D,4,0),"學習周邊") -> 0 | G63: =F63/1.05 -> 0 | H63: =IF(C63="","",TEXT(C63,"YYYY/M/D")*1)
A64: =IFERROR(VLOOKUP(B64,[1]銷貨單品號主檔!$A:$D,4,0),"學習周邊") -> 0 | G64: =F64/1.05 -> 0 | H64: =IF(C64="","",TEXT(C64,"YYYY/M/D")*1)
A65: =IFERROR(VLOOKUP(B65,[1]銷貨單品號主檔!$A:$D,4,0),"學習周邊") -> 0 | G65: =F65/1.05 -> 0 | H65: =IF(C65="","",TEXT(C65,"YYYY/M/D")*1)
A66: =IFERROR(VLOOKUP(B66,[1]銷貨單品號主檔!$A:$D,4,0),"學習周邊") -> 0 | G66: =F66/1.05 -> 0 | H66: =IF(C66="","",TEXT(C66,"YYYY/M/D")*1)
A67: =IFERROR(VLOOKUP(B67,[1]銷貨單品號主檔!$A:$D,4,0),"學習周邊") -> 0 | G67: =F67/1.05 -> 0 | H67: =IF(C67="","",TEXT(C67,"YYYY/M/D")*1)
A68: =IFERROR(VLOOKUP(B68,[1]銷貨單品號主檔!$A:$D,4,0),"學習周邊") -> 0 | G68: =F68/1.05 -> 0 | H68: =IF(C68="","",TEXT(C68,"YYYY/M/D")*1)
A69: =IFERROR(VLOOKUP(B69,[1]銷貨單品號主檔!$A:$D,4,0),"學習周邊") -> 0 | G69: =F69/1.05 -> 0 | H69: =IF(C69="","",TEXT(C69,"YYYY/M/D")*1)
A70: =IFERROR(VLOOKUP(B70,[1]銷貨單品號主檔!$A:$D,4,0),"學習周邊") -> 0 | G70: =F70/1.05 -> 0 | H70: =IF(C70="","",TEXT(C70,"YYYY/M/D")*1)
A71: =IFERROR(VLOOKUP(B71,[1]銷貨單品號主檔!$A:$D,4,0),"學習周邊") -> 0 | G71: =F71/1.05 -> 0 | H71: =IF(C71="","",TEXT(C71,"YYYY/M/D")*1)
A72: =IFERROR(VLOOKUP(B72,[1]銷貨單品號主檔!$A:$D,4,0),"學習周邊") -> 0 | G72: =F72/1.05 -> 0 | H72: =IF(C72="","",TEXT(C72,"YYYY/M/D")*1)
A73: =IFERROR(VLOOKUP(B73,[1]銷貨單品號主檔!$A:$D,4,0),"學習周邊") -> 0 | G73: =F73/1.05 -> 0 | H73: =IF(C73="","",TEXT(C73,"YYYY/M/D")*1)
... A699: =IFERROR(VLOOKUP(B699,[1]銷貨單品號主檔!$A:$D,4,0),"學習周邊") -> 0 | G699: =F699/1.05 -> 0 | H699: =IF(C699="","",TEXT(C699,"YYYY/M/D")*1)

Sheet 2606

Sheet 2607

Sheet 2608

Sheet 2609

Sheet 2610

Sheet 2611

Sheet 2612

Sheet 2701

Sheet 2702

Sheet 2703
